<?xml version="1.0"?><robot name="pi" xmlns:xacro="http://ros.org/wiki/xacro"><material name="b"><color rgba="0.3 0.3 0.3 1"/></material><xacro:macro name="gzc" params="link"><gazebo reference="${link}"><material>Gazebo/Black</material></gazebo></xacro:macro><xacro:macro name="inr"><inertial><mass value="1"/><inertia ixx="0.01" ixy="0.0" ixz="0.0" iyy="0.01" iyz="0.0" izz="0.01"/></inertial></xacro:macro><xacro:macro name="c"><geometry><cylinder length="0.07" radius="0.115"/></geometry></xacro:macro><xacro:macro name="wh" params="n"><link name="${n}_wheel"><visual><xacro:c/><material name="b"/></visual><collision><xacro:c/></collision><xacro:inr/></link></xacro:macro><xacro:macro name="wj" params="n s"><joint name="${n}_wheel_to_axis" type="continuous"><origin rpy="-1.57075 0 0" xyz="-0.15 ${s}0.21 -0.07"/><axis xyz="0 0 1"/><parent link="base_link"/><child link="${n}_wheel"/></joint></xacro:macro><link name="base_link"><visual><geometry><mesh filename="package://my_model/c.dae"/></geometry></visual><collision><geometry><box size="0.5 0.4 0.2"/></geometry><origin xyz="0 0 -0.046"/></collision><xacro:inr/></link><link name="caster"><visual><geometry><sphere radius="0.05"/></geometry><material name="b"/></visual><collision><geometry><sphere radius="0.05"/></geometry></collision><xacro:inr/></link><joint name="base_to_caster" type="continuous"><origin xyz="0.2 0 -0.15"/><axis xyz="0 1 1"/><parent link="base_link"/><child link="caster"/></joint><link name="axis"><visual><geometry><cylinder radius="0.02" length="0.4"/></geometry><origin rpy="1.5708 0 0" xyz="-0.15 0 -0.07"/><material name="b"/></visual></link><joint name="base_to_axis" type="fixed"><parent link="base_link"/><child link="axis"/></joint><xacro:wh n="left"/><xacro:wj n="left" s="-"/><xacro:wh n="right"/><xacro:wj n="right" s=""/><gazebo reference="base_link"><sensor name="imu" type="imu"><always_on>1</always_on><update_rate>100</update_rate><visualize>1</visualize><plugin filename="libgazebo_ros_imu_sensor.so" name="imu_plugin"><topicName>imu</topicName><bodyName>imu</bodyName><updateRateHZ>1.0</updateRateHZ><frameName>imu</frameName></plugin></sensor></gazebo><xacro:gzc link="caster"/><xacro:gzc link="axis"/><xacro:gzc link="left_wheel"/><xacro:gzc link="right_wheel"/><xacro:gzc link="imu"/></robot>